{"uuid": "1c046277-3acd-4042-89e1-0e1cb04d36b0", "children": ["e77cdf12-00b9-4b6c-b460-61283a12908f"], "befores": [{"name": "setup", "status": "broken", "statusDetails": {"message": "urllib3.exceptions.ReadTimeoutError: HTTPConnectionPool(host='localhost', port=40097): Read timed out. (read timeout=120)\n", "trace": "  File \"/usr/local/lib/python3.9/site-packages/pluggy/_callers.py\", line 167, in _multicall\n    teardown.throw(outcome._exception)\n  File \"/usr/local/lib/python3.9/site-packages/_pytest/setuponly.py\", line 36, in pytest_fixture_setup\n    return (yield)\n  File \"/usr/local/lib/python3.9/site-packages/pluggy/_callers.py\", line 103, in _multicall\n    res = hook_impl.function(*args)\n  File \"/usr/local/lib/python3.9/site-packages/_pytest/fixtures.py\", line 1140, in pytest_fixture_setup\n    result = call_fixture_func(fixturefunc, request, kwargs)\n  File \"/usr/local/lib/python3.9/site-packages/_pytest/fixtures.py\", line 891, in call_fixture_func\n    fixture_result = next(generator)\n  File \"/pytest-container/test_cases/conftest.py\", line 252, in setup\n    driver = webdriver.Chrome(service=service, options=options)\n  File \"/usr/local/lib/python3.9/site-packages/selenium/webdriver/chrome/webdriver.py\", line 45, in __init__\n    super().__init__(\n  File \"/usr/local/lib/python3.9/site-packages/selenium/webdriver/chromium/webdriver.py\", line 66, in __init__\n    super().__init__(command_executor=executor, options=options)\n  File \"/usr/local/lib/python3.9/site-packages/selenium/webdriver/remote/webdriver.py\", line 250, in __init__\n    self.start_session(capabilities)\n  File \"/usr/local/lib/python3.9/site-packages/selenium/webdriver/remote/webdriver.py\", line 342, in start_session\n    response = self.execute(Command.NEW_SESSION, caps)[\"value\"]\n  File \"/usr/local/lib/python3.9/site-packages/selenium/webdriver/remote/webdriver.py\", line 427, in execute\n    response = self.command_executor.execute(driver_command, params)\n  File \"/usr/local/lib/python3.9/site-packages/selenium/webdriver/remote/remote_connection.py\", line 404, in execute\n    return self._request(command_info[0], url, body=data)\n  File \"/usr/local/lib/python3.9/site-packages/selenium/webdriver/remote/remote_connection.py\", line 428, in _request\n    response = self._conn.request(method, url, body=body, headers=headers, timeout=self._client_config.timeout)\n  File \"/usr/local/lib/python3.9/site-packages/urllib3/_request_methods.py\", line 143, in request\n    return self.request_encode_body(\n  File \"/usr/local/lib/python3.9/site-packages/urllib3/_request_methods.py\", line 278, in request_encode_body\n    return self.urlopen(method, url, **extra_kw)\n  File \"/usr/local/lib/python3.9/site-packages/urllib3/poolmanager.py\", line 443, in urlopen\n    response = conn.urlopen(method, u.request_uri, **kw)\n  File \"/usr/local/lib/python3.9/site-packages/urllib3/connectionpool.py\", line 841, in urlopen\n    retries = retries.increment(\n  File \"/usr/local/lib/python3.9/site-packages/urllib3/util/retry.py\", line 474, in increment\n    raise reraise(type(error), error, _stacktrace)\n  File \"/usr/local/lib/python3.9/site-packages/urllib3/util/util.py\", line 39, in reraise\n    raise value\n  File \"/usr/local/lib/python3.9/site-packages/urllib3/connectionpool.py\", line 787, in urlopen\n    response = self._make_request(\n  File \"/usr/local/lib/python3.9/site-packages/urllib3/connectionpool.py\", line 536, in _make_request\n    self._raise_timeout(err=e, url=url, timeout_value=read_timeout)\n  File \"/usr/local/lib/python3.9/site-packages/urllib3/connectionpool.py\", line 367, in _raise_timeout\n    raise ReadTimeoutError(\n"}, "start": 1741364476696, "stop": 1741364607964}], "start": 1741364476696, "stop": 1741364608723}